Workbook

Sheet Sheet1_Original_Data
A1: Original Dataset (do not edit — copied as-is from source file)
A3: store_id | B3: month | C3: region | D3: store_type | E3: marketing_spend | F3: footfall | G3: avg_discount_pct | H3: staff_count | I3: inventory_availability_pct | J3: competitor_distance_km | K3: holiday_flag | L3: customer_rating | M3: monthly_sales | N3: monthly_profit
A4: STR-1001 | B4: 2025-01-01 | C4: East | D4: Residential | E4: 70389.11 | F4: 8302 | G4: 0.042 | H4: 17 | I4: 75 | J4: 5.28 | K4: 1 | L4: 3.1 | M4: 658832.62 | N4: 84349.93
A5: STR-1001 | B5: 2025-02-01 | C5: East | D5: Residential | E5: 43827.89 | F5: 8487 | G5: 0.168 | H5: 23 | I5: 84.4 | J5: 4.31 | K5: 0 | L5: 2.8 | M5: 634436 | N5: 106130.54
A6: STR-1001 | B6: 2025-03-01 | C6: East | D6: Residential | E6: 59921.75 | F6: 9113 | G6: 0.133 | H6: 20 | I6: 88 | J6: 12 | K6: 0 | L6: 3.2 | M6: 678722.06 | N6: 101883.86
A7: STR-1001 | B7: 2025-04-01 | C7: East | D7: Residential | E7: 56856.63 | F7: 9431 | G7: 0.142 | H7: 23 | I7: 86.9 | J7: 4.97 | K7: 0 | L7: 3.4 | M7: 658920.3 | N7: 97910.37
A8: STR-1002 | B8: 2025-01-01 | C8: East | D8: High Street | E8: 48412.64 | F8: 9545 | G8: 0.231 | H8: 21 | I8: 97.6 | J8: 6.94 | K8: 1 | L8: 4.2 | M8: 741341.44 | N8: 119208.17
A9: STR-1002 | B9: 2025-02-01 | C9: East | D9: High Street | E9: 64811.21 | F9: 9792 | G9: 0.112 | H9: 20 | I9: 84.2 | J9: 2.88 | K9: 0 | L9: 4.2 | M9: 761835.34 | N9: 149602.23
A10: STR-1002 | B10: 2025-03-01 | C10: East | D10: High Street | E10: 46213.45 | F10: 10616 | G10: 0.122 | H10: 22 | I10: 85.2 | J10: 0.2 | K10: 1 | L10: 4.1 | M10: 806615.54 | N10: 131364.62
A11: STR-1002 | B11: 2025-04-01 | C11: East | D11: High Street | E11: 68148.52 | F11: 8567 | G11: 0.127 | H11: 23 | I11: 95.6 | J11: 0.8 | K11: 0 | L11: 3.9 | M11: 850164.26 | N11: 149262.75
A12: STR-1003 | B12: 2025-01-01 | C12: North | D12: Airport | E12: 71838.86 | F12: 10979 | G12: 0.215 | H12: 26 | I12: 88.6 | J12: 7.7 | K12: 1 | L12: 3.8 | M12: 930581.7 | N12: 136207.98
A13: STR-1003 | B13: 2025-02-01 | C13: North | D13: Airport | E13: 68133.44 | F13: 9459 | G13: 0.22 | H13: 21 | I13: 85 | J13: 1.91 | K13: 0 | L13: 4.2 | M13: 779010.94 | N13: 106328.09
A14: STR-1003 | B14: 2025-03-01 | C14: North | D14: Airport | E14: 34285.21 | F14: 9172 | G14: 0.213 | H14: 22 | I14: 88.3 | J14: 10.46 | K14: 1 | L14: 3.8 | M14: 723060.76 | N14: 123131.24
A15: STR-1003 | B15: 2025-04-01 | C15: North | D15: Airport | E15: 67979.88 | F15: 11230 | G15: 0.002 | H15: 28 | I15: 85.3 | J15: 7.16 | K15: 0 | L15: 3.8 | M15: 910791.94 | N15: 158891.28
... A36: STR-1009 | B36: 2025-01-01 | C36: North | D36: Residential | E36: 54597.83 | F36: 9429 | G36: 0.188 | H36: 21 | I36: 83.3 | J36: 11.71 | K36: 0 | L36: 4.2 | M36: 641865.03 | N36: 81342.58
A37: STR-1009 | B37: 2025-02-01 | C37: North | D37: Residential | E37: 73771.91 | F37: 11695 | G37: 0.07 | H37: 25 | I37: 84.7 | J37: 0.62 | K37: 0 | M37: 799477.76 | N37: 164974.41
A38: STR-1009 | B38: 2025-03-01 | C38: North | D38: Residential | E38: 74413.88 | F38: 9449 | G38: 0.039 | H38: 23 | I38: 92.1 | J38: 2.12 | K38: 0 | L38: 3.5 | M38: 798952.17 | N38: 161499.04
A39: STR-1009 | B39: 2025-04-01 | C39: North | D39: Residential | E39: 52483.77 | F39: 10453 | G39: 0.247 | H39: 25 | I39: 99 | J39: 6.31 | K39: 0 | L39: 3.6 | M39: 800979.78 | N39: 149242.27
A40: STR-1010 | B40: 2025-01-01 | C40: North | D40: Mall | E40: 75269.87 | F40: 8838 | G40: 0.092 | H40: 21 | I40: 83.1 | J40: 9.56 | K40: 1 | L40: 4.2 | M40: 820593.93 | N40: 115860.06
A41: STR-1010 | B41: 2025-02-01 | C41: North | D41: Mall | E41: 61245.41 | F41: 8156 | G41: 0.156 | H41: 19 | I41: 92.9 | J41: 9.05 | K41: 0 | L41: 3.8 | M41: 718330.53 | N41: 93247.9
A42: STR-1010 | B42: 2025-03-01 | C42: North | D42: Mall | E42: 93381.26 | F42: 7562 | G42: 0.198 | H42: 19 | I42: 82.9 | J42: 5.05 | K42: 0 | L42: 4 | M42: 736633.4 | N42: 115654.66
A43: STR-1010 | B43: 2025-04-01 | C43: North | D43: Mall | E43: 65012.19 | F43: 9598 | G43: 0.085 | H43: 24 | I43: 98.3 | J43: 0.89 | K43: 0 | L43: 3.8 | M43: 828623.85 | N43: 167320.52
A44: STR-1011 | B44: 2025-01-01 | C44: East | D44: Mall | E44: 40462.94 | F44: 3660 | G44: 0.218 | H44: 11 | I44: 95.2 | J44: 5.57 | K44: 0 | L44: 4.4 | M44: 592195.85 | N44: 92291.56
A45: STR-1011 | B45: 2025-02-01 | C45: East | D45: Mall | E45: 46123.88 | F45: 3227 | G45: 0.143 | H45: 10 | I45: 75.4 | J45: 1.06 | K45: 0 | L45: 4.4 | M45: 532644.46 | N45: 60681.32
A46: STR-1011 | B46: 2025-03-01 | C46: East | D46: Mall | E46: 68077.54 | F46: 3360 | G46: 0.128 | H46: 14 | I46: 88.2 | J46: 1.24 | K46: 1 | L46: 4 | M46: 657429.18 | N46: 88919.74
A47: STR-1011 | B47: 2025-04-01 | C47: East | D47: Mall | E47: 64882.14 | F47: 3642 | G47: 0.019 | H47: 13 | I47: 87.8 | J47: 4.52 | K47: 0 | L47: 4.2 | M47: 605178 | N47: 106958.74
A48: STR-1012 | B48: 2025-01-01 | C48: West | D48: Residential | E48: 138855.51 | F48: 5145 | G48: 0.06 | H48: 17 | I48: 88.2 | J48: 9.58 | K48: 0 | L48: 3.2 | M48: 595467.6 | N48: 104276.46
A49: STR-1012 | B49: 2025-02-01 | C49: West | D49: Residential | E49: 63630.21 | F49: 4460 | G49: 0.235 | H49: 14 | I49: 98.6 | J49: 5.52 | K49: 0 | L49: 3.5 | M49: 599603.4 | N49: 112685.12
... A74: STR-1018 | B74: 2025-03-01 | C74: East | D74: High Street | E74: 60571.82 | F74: 3193 | G74: 0.197 | H74: 7 | I74: 99 | J74: 1.43 | K74: 0 | L74: 3.2 | M74: 605023.87 | N74: 98545.81
A75: STR-1018 | B75: 2025-04-01 | C75: East | D75: High Street | E75: 55081.16 | F75: 5485 | G75: 0.036 | H75: 12 | I75: 88 | K75: 0 | L75: 3.5 | M75: 674774.09 | N75: 141917.59
A76: STR-1019 | B76: 2025-01-01 | C76: East | D76: Residential | E76: 46201.46 | F76: 5918 | G76: 0.277 | H76: 13 | I76: 78.8 | J76: 4.91 | K76: 0 | L76: 4.5 | M76: 616069.41 | N76: 54453.99
A77: STR-1019 | B77: 2025-02-01 | C77: East | D77: Residential | E77: 53762.92 | F77: 6821 | G77: 0.066 | H77: 19 | I77: 94.6 | J77: 7.03 | K77: 0 | L77: 4.4 | M77: 630829.94 | N77: 117090.02
A78: STR-1019 | B78: 2025-03-01 | C78: East | D78: Residential | E78: 70144.78 | F78: 6806 | G78: 0.178 | H78: 20 | I78: 93.1 | J78: 0.28 | K78: 1 | L78: 4.3 | M78: 788087.68 | N78: 116803.42
A79: STR-1019 | B79: 2025-04-01 | C79: East | D79: Residential | E79: 58749.63 | F79: 8252 | G79: 0.203 | H79: 20 | I79: 85.2 | J79: 3.61 | K79: 0 | L79: 4.5 | M79: 680840.36 | N79: 68007.68
A80: STR-1020 | B80: 2025-01-01 | C80: South | D80: High Street | E80: 56973.18 | F80: 6662 | G80: 0.1 | H80: 15 | I80: 77.7 | J80: 7.52 | K80: 1 | L80: 3.2 | M80: 643657.47 | N80: 87022.45
A81: STR-1020 | B81: 2025-02-01 | C81: South | D81: High Street | E81: 54872.82 | F81: 5962 | G81: 0.064 | H81: 12 | I81: 85.4 | J81: 2.58 | K81: 0 | L81: 2.9 | M81: 691112.6 | N81: 109212.83
A82: STR-1020 | B82: 2025-03-01 | C82: South | D82: High Street | E82: 80562.81 | F82: 7470 | G82: 0.172 | H82: 16 | I82: 83.5 | J82: 2.29 | K82: 0 | L82: 3.3 | M82: 776922.17 | N82: 150701.93
A83: STR-1020 | B83: 2025-04-01 | C83: South | D83: High Street | E83: 77999.9 | F83: 5974 | G83: 0.252 | H83: 14 | I83: 81.3 | J83: 2.39 | K83: 0 | L83: 3.2 | M83: 636561.34 | N83: 93861.06
A84: STR-1021 | B84: 2025-01-01 | C84: West | D84: Mall | E84: 60881.01 | F84: 5410 | G84: 0.179 | H84: 15 | I84: 83.9 | J84: 5.24 | K84: 0 | L84: 4.6 | M84: 621369.58 | N84: 85493.64
A85: STR-1021 | B85: 2025-02-01 | C85: West | D85: Mall | E85: 60628.38 | F85: 4451 | G85: 0.095 | H85: 10 | I85: 89.6 | J85: 3.17 | K85: 0 | L85: 4.6 | M85: 682208.01 | N85: 110318.84
...

Sheet Sheet2_Cleaned_Data
A1: Cleaned & Prepared Data
A2: Missing values in competitor_distance_km and customer_rating were filled with the column median. staff_count, competitor_distance_km, holiday_flag, and monthly_profit are kept for reference but are not used as regression inputs (see README for reasoning).
A4: store_id | B4: month | C4: region | D4: store_type | E4: marketing_spend | F4: footfall | G4: avg_discount_pct | H4: staff_count | I4: inventory_availability_pct | J4: competitor_distance_km | K4: holiday_flag | L4: customer_rating | M4: monthly_sales | N4: monthly_profit | O4: competitor_distance_km_clean | P4: customer_rating_clean
A5: =Sheet1_Original_Data!A4 -> STR-1001 | B5: =Sheet1_Original_Data!B4 -> 2025-01-01 | C5: =Sheet1_Original_Data!C4 -> East | D5: =Sheet1_Original_Data!D4 -> Residential | E5: =Sheet1_Original_Data!E4 -> 70389.11 | F5: =Sheet1_Original_Data!F4 -> 8302 | G5: =Sheet1_Original_Data!G4 -> 0.042 | H5: =Sheet1_Original_Data!H4 -> 17 | ... N5: =Sheet1_Original_Data!N4 -> 84349.93 | O5: =IF(Sheet1_Original_Data!J4="",MEDIAN(Sheet1_Original_Data!$J$4:$J$323),Sheet1_Original_Data!J4) -> 5.28 | P5: =IF(Sheet1_Original_Data!L4="",MEDIAN(Sheet1_Original_Data!$L$4:$L$323),Sheet1_Original_Data!L4) -> 3.1
A6: =Sheet1_Original_Data!A5 -> STR-1001 | B6: =Sheet1_Original_Data!B5 -> 2025-02-01 | C6: =Sheet1_Original_Data!C5 -> East | D6: =Sheet1_Original_Data!D5 -> Residential | E6: =Sheet1_Original_Data!E5 -> 43827.89 | F6: =Sheet1_Original_Data!F5 -> 8487 | G6: =Sheet1_Original_Data!G5 -> 0.168 | H6: =Sheet1_Original_Data!H5 -> 23 | ... N6: =Sheet1_Original_Data!N5 -> 106130.54 | O6: =IF(Sheet1_Original_Data!J5="",MEDIAN(Sheet1_Original_Data!$J$4:$J$323),Sheet1_Original_Data!J5) -> 4.31 | P6: =IF(Sheet1_Original_Data!L5="",MEDIAN(Sheet1_Original_Data!$L$4:$L$323),Sheet1_Original_Data!L5) -> 2.8
A7: =Sheet1_Original_Data!A6 -> STR-1001 | B7: =Sheet1_Original_Data!B6 -> 2025-03-01 | C7: =Sheet1_Original_Data!C6 -> East | D7: =Sheet1_Original_Data!D6 -> Residential | E7: =Sheet1_Original_Data!E6 -> 59921.75 | F7: =Sheet1_Original_Data!F6 -> 9113 | G7: =Sheet1_Original_Data!G6 -> 0.133 | H7: =Sheet1_Original_Data!H6 -> 20 | ... N7: =Sheet1_Original_Data!N6 -> 101883.86 | O7: =IF(Sheet1_Original_Data!J6="",MEDIAN(Sheet1_Original_Data!$J$4:$J$323),Sheet1_Original_Data!J6) -> 12 | P7: =IF(Sheet1_Original_Data!L6="",MEDIAN(Sheet1_Original_Data!$L$4:$L$323),Sheet1_Original_Data!L6) -> 3.2
A8: =Sheet1_Original_Data!A7 -> STR-1001 | B8: =Sheet1_Original_Data!B7 -> 2025-04-01 | C8: =Sheet1_Original_Data!C7 -> East | D8: =Sheet1_Original_Data!D7 -> Residential | E8: =Sheet1_Original_Data!E7 -> 56856.63 | F8: =Sheet1_Original_Data!F7 -> 9431 | G8: =Sheet1_Original_Data!G7 -> 0.142 | H8: =Sheet1_Original_Data!H7 -> 23 | ... N8: =Sheet1_Original_Data!N7 -> 97910.37 | O8: =IF(Sheet1_Original_Data!J7="",MEDIAN(Sheet1_Original_Data!$J$4:$J$323),Sheet1_Original_Data!J7) -> 4.97 | P8: =IF(Sheet1_Original_Data!L7="",MEDIAN(Sheet1_Original_Data!$L$4:$L$323),Sheet1_Original_Data!L7) -> 3.4
A9: =Sheet1_Original_Data!A8 -> STR-1002 | B9: =Sheet1_Original_Data!B8 -> 2025-01-01 | C9: =Sheet1_Original_Data!C8 -> East | D9: =Sheet1_Original_Data!D8 -> High Street | E9: =Sheet1_Original_Data!E8 -> 48412.64 | F9: =Sheet1_Original_Data!F8 -> 9545 | G9: =Sheet1_Original_Data!G8 -> 0.231 | H9: =Sheet1_Original_Data!H8 -> 21 | ... N9: =Sheet1_Original_Data!N8 -> 119208.17 | O9: =IF(Sheet1_Original_Data!J8="",MEDIAN(Sheet1_Original_Data!$J$4:$J$323),Sheet1_Original_Data!J8) -> 6.94 | P9: =IF(Sheet1_Original_Data!L8="",MEDIAN(Sheet1_Original_Data!$L$4:$L$323),Sheet1_Original_Data!L8) -> 4.2
A10: =Sheet1_Original_Data!A9 -> STR-1002 | B10: =Sheet1_Original_Data!B9 -> 2025-02-01 | C10: =Sheet1_Original_Data!C9 -> East | D10: =Sheet1_Original_Data!D9 -> High Street | E10: =Sheet1_Original_Data!E9 -> 64811.21 | F10: =Sheet1_Original_Data!F9 -> 9792 | G10: =Sheet1_Original_Data!G9 -> 0.112 | H10: =Sheet1_Original_Data!H9 -> 20 | ... N10: =Sheet1_Original_Data!N9 -> 149602.23 | O10: =IF(Sheet1_Original_Data!J9="",MEDIAN(Sheet1_Original_Data!$J$4:$J$323),Sheet1_Original_Data!J9) -> 2.88 | P10: =IF(Sheet1_Original_Data!L9="",MEDIAN(Sheet1_Original_Data!$L$4:$L$323),Sheet1_Original_Data!L9) -> 4.2
A11: =Sheet1_Original_Data!A10 -> STR-1002 | B11: =Sheet1_Original_Data!B10 -> 2025-03-01 | C11: =Sheet1_Original_Data!C10 -> East | D11: =Sheet1_Original_Data!D10 -> High Street | E11: =Sheet1_Original_Data!E10 -> 46213.45 | F11: =Sheet1_Original_Data!F10 -> 10616 | G11: =Sheet1_Original_Data!G10 -> 0.122 | H11: =Sheet1_Original_Data!H10 -> 22 | ... N11: =Sheet1_Original_Data!N10 -> 131364.62 | O11: =IF(Sheet1_Original_Data!J10="",MEDIAN(Sheet1_Original_Data!$J$4:$J$323),Sheet1_Original_Data!J10) -> 0.2 | P11: =IF(Sheet1_Original_Data!L10="",MEDIAN(Sheet1_Original_Data!$L$4:$L$323),Sheet1_Original_Data!L10) -> 4.1
A12: =Sheet1_Original_Data!A11 -> STR-1002 | B12: =Sheet1_Original_Data!B11 -> 2025-04-01 | C12: =Sheet1_Original_Data!C11 -> East | D12: =Sheet1_Original_Data!D11 -> High Street | E12: =Sheet1_Original_Data!E11 -> 68148.52 | F12: =Sheet1_Original_Data!F11 -> 8567 | G12: =Sheet1_Original_Data!G11 -> 0.127 | H12: =Sheet1_Original_Data!H11 -> 23 | ... N12: =Sheet1_Original_Data!N11 -> 149262.75 | O12: =IF(Sheet1_Original_Data!J11="",MEDIAN(Sheet1_Original_Data!$J$4:$J$323),Sheet1_Original_Data!J11) -> 0.8 | P12: =IF(Sheet1_Original_Data!L11="",MEDIAN(Sheet1_Original_Data!$L$4:$L$323),Sheet1_Original_Data!L11) -> 3.9
A13: =Sheet1_Original_Data!A12 -> STR-1003 | B13: =Sheet1_Original_Data!B12 -> 2025-01-01 | C13: =Sheet1_Original_Data!C12 -> North | D13: =Sheet1_Original_Data!D12 -> Airport | E13: =Sheet1_Original_Data!E12 -> 71838.86 | F13: =Sheet1_Original_Data!F12 -> 10979 | G13: =Sheet1_Original_Data!G12 -> 0.215 | H13: =Sheet1_Original_Data!H12 -> 26 | ... N13: =Sheet1_Original_Data!N12 -> 136207.98 | O13: =IF(Sheet1_Original_Data!J12="",MEDIAN(Sheet1_Original_Data!$J$4:$J$323),Sheet1_Original_Data!J12) -> 7.7 | P13: =IF(Sheet1_Original_Data!L12="",MEDIAN(Sheet1_Original_Data!$L$4:$L$323),Sheet1_Original_Data!L12) -> 3.8
A14: =Sheet1_Original_Data!A13 -> STR-1003 | B14: =Sheet1_Original_Data!B13 -> 2025-02-01 | C14: =Sheet1_Original_Data!C13 -> North | D14: =Sheet1_Original_Data!D13 -> Airport | E14: =Sheet1_Original_Data!E13 -> 68133.44 | F14: =Sheet1_Original_Data!F13 -> 9459 | G14: =Sheet1_Original_Data!G13 -> 0.22 | H14: =Sheet1_Original_Data!H13 -> 21 | ... N14: =Sheet1_Original_Data!N13 -> 106328.09 | O14: =IF(Sheet1_Original_Data!J13="",MEDIAN(Sheet1_Original_Data!$J$4:$J$323),Sheet1_Original_Data!J13) -> 1.91 | P14: =IF(Sheet1_Original_Data!L13="",MEDIAN(Sheet1_Original_Data!$L$4:$L$323),Sheet1_Original_Data!L13) -> 4.2
A15: =Sheet1_Original_Data!A14 -> STR-1003 | B15: =Sheet1_Original_Data!B14 -> 2025-03-01 | C15: =Sheet1_Original_Data!C14 -> North | D15: =Sheet1_Original_Data!D14 -> Airport | E15: =Sheet1_Original_Data!E14 -> 34285.21 | F15: =Sheet1_Original_Data!F14 -> 9172 | G15: =Sheet1_Original_Data!G14 -> 0.213 | H15: =Sheet1_Original_Data!H14 -> 22 | ... N15: =Sheet1_Original_Data!N14 -> 123131.24 | O15: =IF(Sheet1_Original_Data!J14="",MEDIAN(Sheet1_Original_Data!$J$4:$J$323),Sheet1_Original_Data!J14) -> 10.46 | P15: =IF(Sheet1_Original_Data!L14="",MEDIAN(Sheet1_Original_Data!$L$4:$L$323),Sheet1_Original_Data!L14) -> 3.8
A16: =Sheet1_Original_Data!A15 -> STR-1003 | B16: =Sheet1_Original_Data!B15 -> 2025-04-01 | C16: =Sheet1_Original_Data!C15 -> North | D16: =Sheet1_Original_Data!D15 -> Airport | E16: =Sheet1_Original_Data!E15 -> 67979.88 | F16: =Sheet1_Original_Data!F15 -> 11230 | G16: =Sheet1_Original_Data!G15 -> 0.002 | H16: =Sheet1_Original_Data!H15 -> 28 | ... N16: =Sheet1_Original_Data!N15 -> 158891.28 | O16: =IF(Sheet1_Original_Data!J15="",MEDIAN(Sheet1_Original_Data!$J$4:$J$323),Sheet1_Original_Data!J15) -> 7.16 | P16: =IF(Sheet1_Original_Data!L15="",MEDIAN(Sheet1_Original_Data!$L$4:$L$323),Sheet1_Original_Data!L15) -> 3.8
... A324: =Sheet1_Original_Data!A323 -> STR-1080 | B324: =Sheet1_Original_Data!B323 -> 2025-04-01 | C324: =Sheet1_Original_Data!C323 -> East | D324: =Sheet1_Original_Data!D323 -> Residential | E324: =Sheet1_Original_Data!E323 -> 40553.11 | F324: =Sheet1_Original_Data!F323 -> 5317 | G324: =Sheet1_Original_Data!G323 -> 0.165 | H324: =Sheet1_Original_Data!H323 -> 17 | ... N324: =Sheet1_Original_Data!N323 -> 71443.61 | O324: =IF(Sheet1_Original_Data!J323="",MEDIAN(Sheet1_Original_Data!$J$4:$J$323),Sheet1_Original_Data!J323) -> 11.82 | P324: =IF(Sheet1_Original_Data!L323="",MEDIAN(Sheet1_Original_Data!$L$4:$L$323),Sheet1_Original_Data!L323) -> 4.1

Sheet Sheet3_Dummy_Variables
A1: Dummy Variable Creation
A2: store_type has 4 categories: Airport, High Street, Mall, Residential. High Street is used as the reference category (it is the most common store type), so it does not get its own dummy column — its effect is captured in the model intercept. Each remaining store type gets a 1/0 column: 1 if the store is that type, 0 otherwise.
A4: store_id | B4: month | C4: store_type | D4: st_Airport | E4: st_Mall | F4: st_Residential
A5: =Sheet2_Cleaned_Data!A5 -> STR-1001 | B5: =Sheet2_Cleaned_Data!B5 -> 2025-01-01 | C5: =Sheet2_Cleaned_Data!D5 -> Residential | D5: =IF($C5="Airport",1,0) -> 0 | E5: =IF($C5="Mall",1,0) -> 0 | F5: =IF($C5="Residential",1,0) -> 1
A6: =Sheet2_Cleaned_Data!A6 -> STR-1001 | B6: =Sheet2_Cleaned_Data!B6 -> 2025-02-01 | C6: =Sheet2_Cleaned_Data!D6 -> Residential | D6: =IF($C6="Airport",1,0) -> 0 | E6: =IF($C6="Mall",1,0) -> 0 | F6: =IF($C6="Residential",1,0) -> 1
A7: =Sheet2_Cleaned_Data!A7 -> STR-1001 | B7: =Sheet2_Cleaned_Data!B7 -> 2025-03-01 | C7: =Sheet2_Cleaned_Data!D7 -> Residential | D7: =IF($C7="Airport",1,0) -> 0 | E7: =IF($C7="Mall",1,0) -> 0 | F7: =IF($C7="Residential",1,0) -> 1
A8: =Sheet2_Cleaned_Data!A8 -> STR-1001 | B8: =Sheet2_Cleaned_Data!B8 -> 2025-04-01 | C8: =Sheet2_Cleaned_Data!D8 -> Residential | D8: =IF($C8="Airport",1,0) -> 0 | E8: =IF($C8="Mall",1,0) -> 0 | F8: =IF($C8="Residential",1,0) -> 1
A9: =Sheet2_Cleaned_Data!A9 -> STR-1002 | B9: =Sheet2_Cleaned_Data!B9 -> 2025-01-01 | C9: =Sheet2_Cleaned_Data!D9 -> High Street | D9: =IF($C9="Airport",1,0) -> 0 | E9: =IF($C9="Mall",1,0) -> 0 | F9: =IF($C9="Residential",1,0) -> 0
A10: =Sheet2_Cleaned_Data!A10 -> STR-1002 | B10: =Sheet2_Cleaned_Data!B10 -> 2025-02-01 | C10: =Sheet2_Cleaned_Data!D10 -> High Street | D10: =IF($C10="Airport",1,0) -> 0 | E10: =IF($C10="Mall",1,0) -> 0 | F10: =IF($C10="Residential",1,0) -> 0
A11: =Sheet2_Cleaned_Data!A11 -> STR-1002 | B11: =Sheet2_Cleaned_Data!B11 -> 2025-03-01 | C11: =Sheet2_Cleaned_Data!D11 -> High Street | D11: =IF($C11="Airport",1,0) -> 0 | E11: =IF($C11="Mall",1,0) -> 0 | F11: =IF($C11="Residential",1,0) -> 0
A12: =Sheet2_Cleaned_Data!A12 -> STR-1002 | B12: =Sheet2_Cleaned_Data!B12 -> 2025-04-01 | C12: =Sheet2_Cleaned_Data!D12 -> High Street | D12: =IF($C12="Airport",1,0) -> 0 | E12: =IF($C12="Mall",1,0) -> 0 | F12: =IF($C12="Residential",1,0) -> 0
A13: =Sheet2_Cleaned_Data!A13 -> STR-1003 | B13: =Sheet2_Cleaned_Data!B13 -> 2025-01-01 | C13: =Sheet2_Cleaned_Data!D13 -> Airport | D13: =IF($C13="Airport",1,0) -> 1 | E13: =IF($C13="Mall",1,0) -> 0 | F13: =IF($C13="Residential",1,0) -> 0
A14: =Sheet2_Cleaned_Data!A14 -> STR-1003 | B14: =Sheet2_Cleaned_Data!B14 -> 2025-02-01 | C14: =Sheet2_Cleaned_Data!D14 -> Airport | D14: =IF($C14="Airport",1,0) -> 1 | E14: =IF($C14="Mall",1,0) -> 0 | F14: =IF($C14="Residential",1,0) -> 0
A15: =Sheet2_Cleaned_Data!A15 -> STR-1003 | B15: =Sheet2_Cleaned_Data!B15 -> 2025-03-01 | C15: =Sheet2_Cleaned_Data!D15 -> Airport | D15: =IF($C15="Airport",1,0) -> 1 | E15: =IF($C15="Mall",1,0) -> 0 | F15: =IF($C15="Residential",1,0) -> 0
A16: =Sheet2_Cleaned_Data!A16 -> STR-1003 | B16: =Sheet2_Cleaned_Data!B16 -> 2025-04-01 | C16: =Sheet2_Cleaned_Data!D16 -> Airport | D16: =IF($C16="Airport",1,0) -> 1 | E16: =IF($C16="Mall",1,0) -> 0 | F16: =IF($C16="Residential",1,0) -> 0
... A324: =Sheet2_Cleaned_Data!A324 -> STR-1080 | B324: =Sheet2_Cleaned_Data!B324 -> 2025-04-01 | C324: =Sheet2_Cleaned_Data!D324 -> Residential | D324: =IF($C324="Airport",1,0) -> 0 | E324: =IF($C324="Mall",1,0) -> 0 | F324: =IF($C324="Residential",1,0) -> 1

Sheet Sheet4_Simple_Regression
A1: Simple Linear Regression Models (one predictor at a time)
A2: Dependent variable for all models below: monthly_sales. Formulas use SLOPE, INTERCEPT, RSQ, and LINEST (for p-value via t-stat).
A4: Model: monthly_sales ~ marketing_spend
A5: Intercept (b0) | B5: =INTERCEPT(Sheet2_Cleaned_Data!$M$5:$M$324,Sheet2_Cleaned_Data!$E$5:$E$324) -> 560777.35
A6: Slope (b1) | B6: =SLOPE(Sheet2_Cleaned_Data!$M$5:$M$324,Sheet2_Cleaned_Data!$E$5:$E$324) -> 2.1295753
A7: R-squared | B7: =RSQ(Sheet2_Cleaned_Data!$M$5:$M$324,Sheet2_Cleaned_Data!$E$5:$E$324) -> 0.16724469
A8: t-stat (slope) | B8: =B6/INDEX(LINEST(Sheet2_Cleaned_Data!$M$5:$M$324,Sheet2_Cleaned_Data!$E$5:$E$324,TRUE(),TRUE()),2,1) -> 7.9915501
A9: p-value (slope) | B9: =TDIST(ABS(B8),COUNT(Sheet2_Cleaned_Data!$E$5:$E$324)-2,2) -> 2.4800615e-14
A10: n (observations) | B10: =COUNT(Sheet2_Cleaned_Data!$E$5:$E$324) -> 320
A12: Model: monthly_sales ~ footfall
A13: Intercept (b0) | B13: =INTERCEPT(Sheet2_Cleaned_Data!$M$5:$M$324,Sheet2_Cleaned_Data!$F$5:$F$324) -> 446410.58
A14: Slope (b1) | B14: =SLOPE(Sheet2_Cleaned_Data!$M$5:$M$324,Sheet2_Cleaned_Data!$F$5:$F$324) -> 35.678031
A15: R-squared | B15: =RSQ(Sheet2_Cleaned_Data!$M$5:$M$324,Sheet2_Cleaned_Data!$F$5:$F$324) -> 0.73628534
A16: t-stat (slope) | B16: =B14/INDEX(LINEST(Sheet2_Cleaned_Data!$M$5:$M$324,Sheet2_Cleaned_Data!$F$5:$F$324,TRUE(),TRUE()),2,1) -> 29.796791
A17: p-value (slope) | B17: =TDIST(ABS(B16),COUNT(Sheet2_Cleaned_Data!$F$5:$F$324)-2,2) -> 4.7503615e-94
A18: n (observations) | B18: =COUNT(Sheet2_Cleaned_Data!$F$5:$F$324) -> 320
A20: Model: monthly_sales ~ avg_discount_pct
A21: Intercept (b0) | B21: =INTERCEPT(Sheet2_Cleaned_Data!$M$5:$M$324,Sheet2_Cleaned_Data!$G$5:$G$324) -> 697835.63
A22: Slope (b1) | B22: =SLOPE(Sheet2_Cleaned_Data!$M$5:$M$324,Sheet2_Cleaned_Data!$G$5:$G$324) -> -138730.45
A23: R-squared | B23: =RSQ(Sheet2_Cleaned_Data!$M$5:$M$324,Sheet2_Cleaned_Data!$G$5:$G$324) -> 0.008290503
A24: t-stat (slope) | B24: =B22/INDEX(LINEST(Sheet2_Cleaned_Data!$M$5:$M$324,Sheet2_Cleaned_Data!$G$5:$G$324,TRUE(),TRUE()),2,1) -> -1.6304661
A25: p-value (slope) | B25: =TDIST(ABS(B24),COUNT(Sheet2_Cleaned_Data!$G$5:$G$324)-2,2) -> 0.10399305
A26: n (observations) | B26: =COUNT(Sheet2_Cleaned_Data!$G$5:$G$324) -> 320
A28: Model: monthly_sales ~ inventory_availability_pct
A29: Intercept (b0) | B29: =INTERCEPT(Sheet2_Cleaned_Data!$M$5:$M$324,Sheet2_Cleaned_Data!$I$5:$I$324) -> 484814.26
A30: Slope (b1) | B30: =SLOPE(Sheet2_Cleaned_Data!$M$5:$M$324,Sheet2_Cleaned_Data!$I$5:$I$324) -> 2217.8319
A31: R-squared | B31: =RSQ(Sheet2_Cleaned_Data!$M$5:$M$324,Sheet2_Cleaned_Data!$I$5:$I$324) -> 0.013115016
A32: t-stat (slope) | B32: =B30/INDEX(LINEST(Sheet2_Cleaned_Data!$M$5:$M$324,Sheet2_Cleaned_Data!$I$5:$I$324,TRUE(),TRUE()),2,1) -> 2.0557235
A33: p-value (slope) | B33: =TDIST(ABS(B32),COUNT(Sheet2_Cleaned_Data!$I$5:$I$324)-2,2) -> 0.040625297
A34: n (observations) | B34: =COUNT(Sheet2_Cleaned_Data!$I$5:$I$324) -> 320
A36: Model: monthly_sales ~ customer_rating (cleaned)
A37: Intercept (b0) | B37: =INTERCEPT(Sheet2_Cleaned_Data!$M$5:$M$324,Sheet2_Cleaned_Data!$P$5:$P$324) -> 701366.86
A38: Slope (b1) | B38: =SLOPE(Sheet2_Cleaned_Data!$M$5:$M$324,Sheet2_Cleaned_Data!$P$5:$P$324) -> -5284.8663
A39: R-squared | B39: =RSQ(Sheet2_Cleaned_Data!$M$5:$M$324,Sheet2_Cleaned_Data!$P$5:$P$324) -> 0.00069845266
A40: t-stat (slope) | B40: =B38/INDEX(LINEST(Sheet2_Cleaned_Data!$M$5:$M$324,Sheet2_Cleaned_Data!$P$5:$P$324,TRUE(),TRUE()),2,1) -> -0.47144797
A41: p-value (slope) | B41: =TDIST(ABS(B40),COUNT(Sheet2_Cleaned_Data!$P$5:$P$324)-2,2) -> 0.63764415
A42: n (observations) | B42: =COUNT(Sheet2_Cleaned_Data!$P$5:$P$324) -> 320

Sheet Sheet5_Multiple_Regression
A1: Multiple Regression Model
A2: Predictors: marketing_spend, footfall, avg_discount_pct, inventory_availability_pct (numeric) plus st_Airport, st_Mall, st_Residential (dummy variables, reference = High Street). LINEST returns coefficients in reverse column order (last predictor first), handled below.
A4: Predictor block (X range used by LINEST) | J4: Multiple Regression Results (via LINEST)
A5: marketing_spend | B5: footfall | C5: avg_discount_pct | D5: inventory_availability_pct | E5: st_Airport | F5: st_Mall | G5: st_Residential | I5: Variable | J5: Coefficient | K5: Std Error | L5: t-stat | M5: p-value
A6: =Sheet2_Cleaned_Data!E5 -> 70389.11 | B6: =Sheet2_Cleaned_Data!F5 -> 8302 | C6: =Sheet2_Cleaned_Data!G5 -> 0.042 | D6: =Sheet2_Cleaned_Data!I5 -> 75 | E6: =Sheet3_Dummy_Variables!D5 -> 0 | F6: =Sheet3_Dummy_Variables!E5 -> 0 | G6: =Sheet3_Dummy_Variables!F5 -> 1 | I6: Intercept | J6: =INDEX(LINEST(Sheet2_Cleaned_Data!$M$5:$M$324,$A$6:$G$325,TRUE(),TRUE()),1,8) -> 136913.65 | K6: =INDEX(LINEST(Sheet2_Cleaned_Data!$M$5:$M$324,$A$6:$G$325,TRUE(),TRUE()),2,8) -> 43429.51 | L6: =J6/K6 -> 3.1525487 | M6: =TDIST(ABS(L6),(COUNT(Sheet2_Cleaned_Data!$M$5:$M$324)-7-1),2) -> 0.0017758246
A7: =Sheet2_Cleaned_Data!E6 -> 43827.89 | B7: =Sheet2_Cleaned_Data!F6 -> 8487 | C7: =Sheet2_Cleaned_Data!G6 -> 0.168 | D7: =Sheet2_Cleaned_Data!I6 -> 84.4 | E7: =Sheet3_Dummy_Variables!D6 -> 0 | F7: =Sheet3_Dummy_Variables!E6 -> 0 | G7: =Sheet3_Dummy_Variables!F6 -> 1 | I7: marketing_spend | J7: =INDEX(LINEST(Sheet2_Cleaned_Data!$M$5:$M$324,$A$6:$G$325,TRUE(),TRUE()),1,7) -> 1.1654929 | K7: =INDEX(LINEST(Sheet2_Cleaned_Data!$M$5:$M$324,$A$6:$G$325,TRUE(),TRUE()),2,7) -> 0.12848737 | L7: =J7/K7 -> 9.0708754 | M7: =TDIST(ABS(L7),(COUNT(Sheet2_Cleaned_Data!$M$5:$M$324)-7-1),2) -> 1.3555461e-17
A8: =Sheet2_Cleaned_Data!E7 -> 59921.75 | B8: =Sheet2_Cleaned_Data!F7 -> 9113 | C8: =Sheet2_Cleaned_Data!G7 -> 0.133 | D8: =Sheet2_Cleaned_Data!I7 -> 88 | E8: =Sheet3_Dummy_Variables!D7 -> 0 | F8: =Sheet3_Dummy_Variables!E7 -> 0 | G8: =Sheet3_Dummy_Variables!F7 -> 1 | I8: footfall | J8: =INDEX(LINEST(Sheet2_Cleaned_Data!$M$5:$M$324,$A$6:$G$325,TRUE(),TRUE()),1,6) -> 33.664405 | K8: =INDEX(LINEST(Sheet2_Cleaned_Data!$M$5:$M$324,$A$6:$G$325,TRUE(),TRUE()),2,6) -> 1.0308343 | L8: =J8/K8 -> 32.657435 | M8: =TDIST(ABS(L8),(COUNT(Sheet2_Cleaned_Data!$M$5:$M$324)-7-1),2) -> 1.1222697e-102
A9: =Sheet2_Cleaned_Data!E8 -> 56856.63 | B9: =Sheet2_Cleaned_Data!F8 -> 9431 | C9: =Sheet2_Cleaned_Data!G8 -> 0.142 | D9: =Sheet2_Cleaned_Data!I8 -> 86.9 | E9: =Sheet3_Dummy_Variables!D8 -> 0 | F9: =Sheet3_Dummy_Variables!E8 -> 0 | G9: =Sheet3_Dummy_Variables!F8 -> 1 | I9: avg_discount_pct | J9: =INDEX(LINEST(Sheet2_Cleaned_Data!$M$5:$M$324,$A$6:$G$325,TRUE(),TRUE()),1,5) -> -58920.807 | K9: =INDEX(LINEST(Sheet2_Cleaned_Data!$M$5:$M$324,$A$6:$G$325,TRUE(),TRUE()),2,5) -> 36743.021 | L9: =J9/K9 -> -1.6035918 | M9: =TDIST(ABS(L9),(COUNT(Sheet2_Cleaned_Data!$M$5:$M$324)-7-1),2) -> 0.10981586
A10: =Sheet2_Cleaned_Data!E9 -> 48412.64 | B10: =Sheet2_Cleaned_Data!F9 -> 9545 | C10: =Sheet2_Cleaned_Data!G9 -> 0.231 | D10: =Sheet2_Cleaned_Data!I9 -> 97.6 | E10: =Sheet3_Dummy_Variables!D9 -> 0 | F10: =Sheet3_Dummy_Variables!E9 -> 0 | G10: =Sheet3_Dummy_Variables!F9 -> 0 | I10: inventory_availability_pct | J10: =INDEX(LINEST(Sheet2_Cleaned_Data!$M$5:$M$324,$A$6:$G$325,TRUE(),TRUE()),1,4) -> 3001.1957 | K10: =INDEX(LINEST(Sheet2_Cleaned_Data!$M$5:$M$324,$A$6:$G$325,TRUE(),TRUE()),2,4) -> 466.59755 | L10: =J10/K10 -> 6.4320862 | M10: =TDIST(ABS(L10),(COUNT(Sheet2_Cleaned_Data!$M$5:$M$324)-7-1),2) -> 4.7245685e-10
A11: =Sheet2_Cleaned_Data!E10 -> 64811.21 | B11: =Sheet2_Cleaned_Data!F10 -> 9792 | C11: =Sheet2_Cleaned_Data!G10 -> 0.112 | D11: =Sheet2_Cleaned_Data!I10 -> 84.2 | E11: =Sheet3_Dummy_Variables!D10 -> 0 | F11: =Sheet3_Dummy_Variables!E10 -> 0 | G11: =Sheet3_Dummy_Variables!F10 -> 0 | I11: st_Airport | J11: =INDEX(LINEST(Sheet2_Cleaned_Data!$M$5:$M$324,$A$6:$G$325,TRUE(),TRUE()),1,3) -> 21905.715 | K11: =INDEX(LINEST(Sheet2_Cleaned_Data!$M$5:$M$324,$A$6:$G$325,TRUE(),TRUE()),2,3) -> 9402.0876 | L11: =J11/K11 -> 2.3298777 | M11: =TDIST(ABS(L11),(COUNT(Sheet2_Cleaned_Data!$M$5:$M$324)-7-1),2) -> 0.020450265
A12: =Sheet2_Cleaned_Data!E11 -> 46213.45 | B12: =Sheet2_Cleaned_Data!F11 -> 10616 | C12: =Sheet2_Cleaned_Data!G11 -> 0.122 | D12: =Sheet2_Cleaned_Data!I11 -> 85.2 | E12: =Sheet3_Dummy_Variables!D11 -> 0 | F12: =Sheet3_Dummy_Variables!E11 -> 0 | G12: =Sheet3_Dummy_Variables!F11 -> 0 | I12: st_Mall | J12: =INDEX(LINEST(Sheet2_Cleaned_Data!$M$5:$M$324,$A$6:$G$325,TRUE(),TRUE()),1,2) -> 11433.464 | K12: =INDEX(LINEST(Sheet2_Cleaned_Data!$M$5:$M$324,$A$6:$G$325,TRUE(),TRUE()),2,2) -> 6578.0772 | L12: =J12/K12 -> 1.7381164 | M12: =TDIST(ABS(L12),(COUNT(Sheet2_Cleaned_Data!$M$5:$M$324)-7-1),2) -> 0.083176903
A13: =Sheet2_Cleaned_Data!E12 -> 68148.52 | B13: =Sheet2_Cleaned_Data!F12 -> 8567 | C13: =Sheet2_Cleaned_Data!G12 -> 0.127 | D13: =Sheet2_Cleaned_Data!I12 -> 95.6 | E13: =Sheet3_Dummy_Variables!D12 -> 0 | F13: =Sheet3_Dummy_Variables!E12 -> 0 | G13: =Sheet3_Dummy_Variables!F12 -> 0 | I13: st_Residential | J13: =INDEX(LINEST(Sheet2_Cleaned_Data!$M$5:$M$324,$A$6:$G$325,TRUE(),TRUE()),1,1) -> -16575.848 | K13: =INDEX(LINEST(Sheet2_Cleaned_Data!$M$5:$M$324,$A$6:$G$325,TRUE(),TRUE()),2,1) -> 6085.6267 | L13: =J13/K13 -> -2.7237701 | M13: =TDIST(ABS(L13),(COUNT(Sheet2_Cleaned_Data!$M$5:$M$324)-7-1),2) -> 0.0068177238
A14: =Sheet2_Cleaned_Data!E13 -> 71838.86 | B14: =Sheet2_Cleaned_Data!F13 -> 10979 | C14: =Sheet2_Cleaned_Data!G13 -> 0.215 | D14: =Sheet2_Cleaned_Data!I13 -> 88.6 | E14: =Sheet3_Dummy_Variables!D13 -> 1 | F14: =Sheet3_Dummy_Variables!E13 -> 0 | G14: =Sheet3_Dummy_Variables!F13 -> 0
A15: =Sheet2_Cleaned_Data!E14 -> 68133.44 | B15: =Sheet2_Cleaned_Data!F14 -> 9459 | C15: =Sheet2_Cleaned_Data!G14 -> 0.22 | D15: =Sheet2_Cleaned_Data!I14 -> 85 | E15: =Sheet3_Dummy_Variables!D14 -> 1 | F15: =Sheet3_Dummy_Variables!E14 -> 0 | G15: =Sheet3_Dummy_Variables!F14 -> 0 | I15: R-squared | J15: =INDEX(LINEST(Sheet2_Cleaned_Data!$M$5:$M$324,$A$6:$G$325,TRUE(),TRUE()),3,1) -> 0.82139228
A16: =Sheet2_Cleaned_Data!E15 -> 34285.21 | B16: =Sheet2_Cleaned_Data!F15 -> 9172 | C16: =Sheet2_Cleaned_Data!G15 -> 0.213 | D16: =Sheet2_Cleaned_Data!I15 -> 88.3 | E16: =Sheet3_Dummy_Variables!D15 -> 1 | F16: =Sheet3_Dummy_Variables!E15 -> 0 | G16: =Sheet3_Dummy_Variables!F15 -> 0 | I16: F-statistic | J16: =INDEX(LINEST(Sheet2_Cleaned_Data!$M$5:$M$324,$A$6:$G$325,TRUE(),TRUE()),4,1) -> 204.97785
A17: =Sheet2_Cleaned_Data!E16 -> 67979.88 | B17: =Sheet2_Cleaned_Data!F16 -> 11230 | C17: =Sheet2_Cleaned_Data!G16 -> 0.002 | D17: =Sheet2_Cleaned_Data!I16 -> 85.3 | E17: =Sheet3_Dummy_Variables!D16 -> 1 | F17: =Sheet3_Dummy_Variables!E16 -> 0 | G17: =Sheet3_Dummy_Variables!F16 -> 0 | I17: n (observations) | J17: =COUNT(Sheet2_Cleaned_Data!$M$5:$M$324) -> 320
A18: =Sheet2_Cleaned_Data!E17 -> 71828.26 | B18: =Sheet2_Cleaned_Data!F17 -> 12775 | C18: =Sheet2_Cleaned_Data!G17 -> 0.116 | D18: =Sheet2_Cleaned_Data!I17 -> 81.7 | E18: =Sheet3_Dummy_Variables!D17 -> 0 | F18: =Sheet3_Dummy_Variables!E17 -> 0 | G18: =Sheet3_Dummy_Variables!F17 -> 1
A19: =Sheet2_Cleaned_Data!E18 -> 55716.82 | B19: =Sheet2_Cleaned_Data!F18 -> 10054 | C19: =Sheet2_Cleaned_Data!G18 -> 0.146 | D19: =Sheet2_Cleaned_Data!I18 -> 84.9 | E19: =Sheet3_Dummy_Variables!D18 -> 0 | F19: =Sheet3_Dummy_Variables!E18 -> 0 | G19: =Sheet3_Dummy_Variables!F18 -> 1
A20: =Sheet2_Cleaned_Data!E19 -> 59909.51 | B20: =Sheet2_Cleaned_Data!F19 -> 8895 | C20: =Sheet2_Cleaned_Data!G19 -> 0.228 | D20: =Sheet2_Cleaned_Data!I19 -> 88.8 | E20: =Sheet3_Dummy_Variables!D19 -> 0 | F20: =Sheet3_Dummy_Variables!E19 -> 0 | G20: =Sheet3_Dummy_Variables!F19 -> 1
A21: =Sheet2_Cleaned_Data!E20 -> 75305.71 | B21: =Sheet2_Cleaned_Data!F20 -> 10940 | C21: =Sheet2_Cleaned_Data!G20 -> 0.006 | D21: =Sheet2_Cleaned_Data!I20 -> 76.5 | E21: =Sheet3_Dummy_Variables!D20 -> 0 | F21: =Sheet3_Dummy_Variables!E20 -> 0 | G21: =Sheet3_Dummy_Variables!F20 -> 1
A22: =Sheet2_Cleaned_Data!E21 -> 48804.22 | B22: =Sheet2_Cleaned_Data!F21 -> 7057 | C22: =Sheet2_Cleaned_Data!G21 -> 0.005 | D22: =Sheet2_Cleaned_Data!I21 -> 87.7 | E22: =Sheet3_Dummy_Variables!D21 -> 0 | F22: =Sheet3_Dummy_Variables!E21 -> 0 | G22: =Sheet3_Dummy_Variables!F21 -> 1
A23: =Sheet2_Cleaned_Data!E22 -> 59117.9 | B23: =Sheet2_Cleaned_Data!F22 -> 4263 | C23: =Sheet2_Cleaned_Data!G22 -> 0.119 | D23: =Sheet2_Cleaned_Data!I22 -> 87.6 | E23: =Sheet3_Dummy_Variables!D22 -> 0 | F23: =Sheet3_Dummy_Variables!E22 -> 0 | G23: =Sheet3_Dummy_Variables!F22 -> 1
A24: =Sheet2_Cleaned_Data!E23 -> 78831.12 | B24: =Sheet2_Cleaned_Data!F23 -> 5538 | C24: =Sheet2_Cleaned_Data!G23 -> 0 | D24: =Sheet2_Cleaned_Data!I23 -> 94.1 | E24: =Sheet3_Dummy_Variables!D23 -> 0 | F24: =Sheet3_Dummy_Variables!E23 -> 0 | G24: =Sheet3_Dummy_Variables!F23 -> 1
A25: =Sheet2_Cleaned_Data!E24 -> 41441.93 | B25: =Sheet2_Cleaned_Data!F24 -> 4865 | C25: =Sheet2_Cleaned_Data!G24 -> 0.158 | D25: =Sheet2_Cleaned_Data!I24 -> 88.3 | E25: =Sheet3_Dummy_Variables!D24 -> 0 | F25: =Sheet3_Dummy_Variables!E24 -> 0 | G25: =Sheet3_Dummy_Variables!F24 -> 1
A26: =Sheet2_Cleaned_Data!E25 -> 30356.28 | B26: =Sheet2_Cleaned_Data!F25 -> 2822 | C26: =Sheet2_Cleaned_Data!G25 -> 0.231 | D26: =Sheet2_Cleaned_Data!I25 -> 84.8 | E26: =Sheet3_Dummy_Variables!D25 -> 0 | F26: =Sheet3_Dummy_Variables!E25 -> 0 | G26: =Sheet3_Dummy_Variables!F25 -> 1
A27: =Sheet2_Cleaned_Data!E26 -> 33518.88 | B27: =Sheet2_Cleaned_Data!F26 -> 2121 | C27: =Sheet2_Cleaned_Data!G26 -> 0.176 | D27: =Sheet2_Cleaned_Data!I26 -> 88.5 | E27: =Sheet3_Dummy_Variables!D26 -> 0 | F27: =Sheet3_Dummy_Variables!E26 -> 0 | G27: =Sheet3_Dummy_Variables!F26 -> 1
A28: =Sheet2_Cleaned_Data!E27 -> 42267.37 | B28: =Sheet2_Cleaned_Data!F27 -> 3364 | C28: =Sheet2_Cleaned_Data!G27 -> 0.16 | D28: =Sheet2_Cleaned_Data!I27 -> 82 | E28: =Sheet3_Dummy_Variables!D27 -> 0 | F28: =Sheet3_Dummy_Variables!E27 -> 0 | G28: =Sheet3_Dummy_Variables!F27 -> 1
A29: =Sheet2_Cleaned_Data!E28 -> 62060.43 | B29: =Sheet2_Cleaned_Data!F28 -> 2613 | C29: =Sheet2_Cleaned_Data!G28 -> 0.216 | D29: =Sheet2_Cleaned_Data!I28 -> 92.1 | E29: =Sheet3_Dummy_Variables!D28 -> 0 | F29: =Sheet3_Dummy_Variables!E28 -> 0 | G29: =Sheet3_Dummy_Variables!F28 -> 1
... A325: =Sheet2_Cleaned_Data!E324 -> 40553.11 | B325: =Sheet2_Cleaned_Data!F324 -> 5317 | C325: =Sheet2_Cleaned_Data!G324 -> 0.165 | D325: =Sheet2_Cleaned_Data!I324 -> 84.3 | E325: =Sheet3_Dummy_Variables!D324 -> 0 | F325: =Sheet3_Dummy_Variables!E324 -> 0 | G325: =Sheet3_Dummy_Variables!F324 -> 1

Sheet Sheet6_Predictions_Residuals
A1: Predicted Sales and Residuals (final model = Multiple Regression)
A2: predicted_sales uses the coefficients from sheet 5_Multiple_Regression. residual = actual sales minus predicted sales.
A4: store_id | B4: month | C4: region | D4: store_type | E4: actual_sales | F4: predicted_sales | G4: residual | I4: Top 5 Largest Positive Residuals (model under-predicts)
A5: =Sheet2_Cleaned_Data!A5 -> STR-1001 | B5: =Sheet2_Cleaned_Data!B5 -> 2025-01-01 | C5: =Sheet2_Cleaned_Data!C5 -> East | D5: =Sheet2_Cleaned_Data!D5 -> Residential | E5: =Sheet2_Cleaned_Data!M5 -> 658832.62 | F5: =Sheet5_Multiple_Regression!$J$6+Sheet5_Multiple_Regression!$J$7*Sheet5_Multiple_Regression!A6+Sheet5_Multiple_Regression!$J$8*Sheet5_Multiple_Regression!B6+Sheet5_Multiple_Regression!$J$9*Sheet5_Multiple_Regression!C6+Sheet5_Multiple_Regression!$J$10*Sheet5_Multiple_Regression!D6+Sheet5_Multiple_Regression!$J$11*Sheet5_Multiple_Regression!E6+Sheet5_Multiple_Regression!$J$12*Sheet5_Multiple_Regression!F6+Sheet5_Multiple_Regression!$J$13*Sheet5_Multiple_Regression!G6 -> 704472.7 | G5: =E5-F5 -> -45640.084 | I5: Rank | J5: store_id | K5: store_type | L5: region | M5: residual
A6: =Sheet2_Cleaned_Data!A6 -> STR-1001 | B6: =Sheet2_Cleaned_Data!B6 -> 2025-02-01 | C6: =Sheet2_Cleaned_Data!C6 -> East | D6: =Sheet2_Cleaned_Data!D6 -> Residential | E6: =Sheet2_Cleaned_Data!M6 -> 634436 | F6: =Sheet5_Multiple_Regression!$J$6+Sheet5_Multiple_Regression!$J$7*Sheet5_Multiple_Regression!A7+Sheet5_Multiple_Regression!$J$8*Sheet5_Multiple_Regression!B7+Sheet5_Multiple_Regression!$J$9*Sheet5_Multiple_Regression!C7+Sheet5_Multiple_Regression!$J$10*Sheet5_Multiple_Regression!D7+Sheet5_Multiple_Regression!$J$11*Sheet5_Multiple_Regression!E7+Sheet5_Multiple_Regression!$J$12*Sheet5_Multiple_Regression!F7+Sheet5_Multiple_Regression!$J$13*Sheet5_Multiple_Regression!G7 -> 700530.92 | G6: =E6-F6 -> -66094.922 | I6: 1 | J6: =INDEX($A$5:$A$324,MATCH(M6,$G$5:$G$324,0)) -> STR-1030 | K6: =INDEX($D$5:$D$324,MATCH(M6,$G$5:$G$324,0)) -> Residential | L6: =INDEX($C$5:$C$324,MATCH(M6,$G$5:$G$324,0)) -> West | M6: =LARGE($G$5:$G$324,1) -> 105899.45
A7: =Sheet2_Cleaned_Data!A7 -> STR-1001 | B7: =Sheet2_Cleaned_Data!B7 -> 2025-03-01 | C7: =Sheet2_Cleaned_Data!C7 -> East | D7: =Sheet2_Cleaned_Data!D7 -> Residential | E7: =Sheet2_Cleaned_Data!M7 -> 678722.06 | F7: =Sheet5_Multiple_Regression!$J$6+Sheet5_Multiple_Regression!$J$7*Sheet5_Multiple_Regression!A8+Sheet5_Multiple_Regression!$J$8*Sheet5_Multiple_Regression!B8+Sheet5_Multiple_Regression!$J$9*Sheet5_Multiple_Regression!C8+Sheet5_Multiple_Regression!$J$10*Sheet5_Multiple_Regression!D8+Sheet5_Multiple_Regression!$J$11*Sheet5_Multiple_Regression!E8+Sheet5_Multiple_Regression!$J$12*Sheet5_Multiple_Regression!F8+Sheet5_Multiple_Regression!$J$13*Sheet5_Multiple_Regression!G8 -> 753228.65 | G7: =E7-F7 -> -74506.593 | I7: 2 | J7: =INDEX($A$5:$A$324,MATCH(M7,$G$5:$G$324,0)) -> STR-1073 | K7: =INDEX($D$5:$D$324,MATCH(M7,$G$5:$G$324,0)) -> Residential | L7: =INDEX($C$5:$C$324,MATCH(M7,$G$5:$G$324,0)) -> East | M7: =LARGE($G$5:$G$324,2) -> 99623.41
A8: =Sheet2_Cleaned_Data!A8 -> STR-1001 | B8: =Sheet2_Cleaned_Data!B8 -> 2025-04-01 | C8: =Sheet2_Cleaned_Data!C8 -> East | D8: =Sheet2_Cleaned_Data!D8 -> Residential | E8: =Sheet2_Cleaned_Data!M8 -> 658920.3 | F8: =Sheet5_Multiple_Regression!$J$6+Sheet5_Multiple_Regression!$J$7*Sheet5_Multiple_Regression!A9+Sheet5_Multiple_Regression!$J$8*Sheet5_Multiple_Regression!B9+Sheet5_Multiple_Regression!$J$9*Sheet5_Multiple_Regression!C9+Sheet5_Multiple_Regression!$J$10*Sheet5_Multiple_Regression!D9+Sheet5_Multiple_Regression!$J$11*Sheet5_Multiple_Regression!E9+Sheet5_Multiple_Regression!$J$12*Sheet5_Multiple_Regression!F9+Sheet5_Multiple_Regression!$J$13*Sheet5_Multiple_Regression!G9 -> 756529.96 | G8: =E8-F8 -> -97609.655 | I8: 3 | J8: =INDEX($A$5:$A$324,MATCH(M8,$G$5:$G$324,0)) -> STR-1032 | K8: =INDEX($D$5:$D$324,MATCH(M8,$G$5:$G$324,0)) -> High Street | L8: =INDEX($C$5:$C$324,MATCH(M8,$G$5:$G$324,0)) -> South | M8: =LARGE($G$5:$G$324,3) -> 98771.441
A9: =Sheet2_Cleaned_Data!A9 -> STR-1002 | B9: =Sheet2_Cleaned_Data!B9 -> 2025-01-01 | C9: =Sheet2_Cleaned_Data!C9 -> East | D9: =Sheet2_Cleaned_Data!D9 -> High Street | E9: =Sheet2_Cleaned_Data!M9 -> 741341.44 | F9: =Sheet5_Multiple_Regression!$J$6+Sheet5_Multiple_Regression!$J$7*Sheet5_Multiple_Regression!A10+Sheet5_Multiple_Regression!$J$8*Sheet5_Multiple_Regression!B10+Sheet5_Multiple_Regression!$J$9*Sheet5_Multiple_Regression!C10+Sheet5_Multiple_Regression!$J$10*Sheet5_Multiple_Regression!D10+Sheet5_Multiple_Regression!$J$11*Sheet5_Multiple_Regression!E10+Sheet5_Multiple_Regression!$J$12*Sheet5_Multiple_Regression!F10+Sheet5_Multiple_Regression!$J$13*Sheet5_Multiple_Regression!G10 -> 793970.98 | G9: =E9-F9 -> -52629.537 | I9: 4 | J9: =INDEX($A$5:$A$324,MATCH(M9,$G$5:$G$324,0)) -> STR-1050 | K9: =INDEX($D$5:$D$324,MATCH(M9,$G$5:$G$324,0)) -> Residential | L9: =INDEX($C$5:$C$324,MATCH(M9,$G$5:$G$324,0)) -> North | M9: =LARGE($G$5:$G$324,4) -> 97246.493
A10: =Sheet2_Cleaned_Data!A10 -> STR-1002 | B10: =Sheet2_Cleaned_Data!B10 -> 2025-02-01 | C10: =Sheet2_Cleaned_Data!C10 -> East | D10: =Sheet2_Cleaned_Data!D10 -> High Street | E10: =Sheet2_Cleaned_Data!M10 -> 761835.34 | F10: =Sheet5_Multiple_Regression!$J$6+Sheet5_Multiple_Regression!$J$7*Sheet5_Multiple_Regression!A11+Sheet5_Multiple_Regression!$J$8*Sheet5_Multiple_Regression!B11+Sheet5_Multiple_Regression!$J$9*Sheet5_Multiple_Regression!C11+Sheet5_Multiple_Regression!$J$10*Sheet5_Multiple_Regression!D11+Sheet5_Multiple_Regression!$J$11*Sheet5_Multiple_Regression!E11+Sheet5_Multiple_Regression!$J$12*Sheet5_Multiple_Regression!F11+Sheet5_Multiple_Regression!$J$13*Sheet5_Multiple_Regression!G11 -> 788194.06 | G10: =E10-F10 -> -26358.716 | I10: 5 | J10: =INDEX($A$5:$A$324,MATCH(M10,$G$5:$G$324,0)) -> STR-1028 | K10: =INDEX($D$5:$D$324,MATCH(M10,$G$5:$G$324,0)) -> Mall | L10: =INDEX($C$5:$C$324,MATCH(M10,$G$5:$G$324,0)) -> East | M10: =LARGE($G$5:$G$324,5) -> 95145.324
A11: =Sheet2_Cleaned_Data!A11 -> STR-1002 | B11: =Sheet2_Cleaned_Data!B11 -> 2025-03-01 | C11: =Sheet2_Cleaned_Data!C11 -> East | D11: =Sheet2_Cleaned_Data!D11 -> High Street | E11: =Sheet2_Cleaned_Data!M11 -> 806615.54 | F11: =Sheet5_Multiple_Regression!$J$6+Sheet5_Multiple_Regression!$J$7*Sheet5_Multiple_Regression!A12+Sheet5_Multiple_Regression!$J$8*Sheet5_Multiple_Regression!B12+Sheet5_Multiple_Regression!$J$9*Sheet5_Multiple_Regression!C12+Sheet5_Multiple_Regression!$J$10*Sheet5_Multiple_Regression!D12+Sheet5_Multiple_Regression!$J$11*Sheet5_Multiple_Regression!E12+Sheet5_Multiple_Regression!$J$12*Sheet5_Multiple_Regression!F12+Sheet5_Multiple_Regression!$J$13*Sheet5_Multiple_Regression!G12 -> 796669.96 | G11: =E11-F11 -> 9945.5847
A12: =Sheet2_Cleaned_Data!A12 -> STR-1002 | B12: =Sheet2_Cleaned_Data!B12 -> 2025-04-01 | C12: =Sheet2_Cleaned_Data!C12 -> East | D12: =Sheet2_Cleaned_Data!D12 -> High Street | E12: =Sheet2_Cleaned_Data!M12 -> 850164.26 | F12: =Sheet5_Multiple_Regression!$J$6+Sheet5_Multiple_Regression!$J$7*Sheet5_Multiple_Regression!A13+Sheet5_Multiple_Regression!$J$8*Sheet5_Multiple_Regression!B13+Sheet5_Multiple_Regression!$J$9*Sheet5_Multiple_Regression!C13+Sheet5_Multiple_Regression!$J$10*Sheet5_Multiple_Regression!D13+Sheet5_Multiple_Regression!$J$11*Sheet5_Multiple_Regression!E13+Sheet5_Multiple_Regression!$J$12*Sheet5_Multiple_Regression!F13+Sheet5_Multiple_Regression!$J$13*Sheet5_Multiple_Regression!G13 -> 784174.59 | G12: =E12-F12 -> 65989.67 | I12: Top 5 Largest Negative Residuals (model over-predicts)
A13: =Sheet2_Cleaned_Data!A13 -> STR-1003 | B13: =Sheet2_Cleaned_Data!B13 -> 2025-01-01 | C13: =Sheet2_Cleaned_Data!C13 -> North | D13: =Sheet2_Cleaned_Data!D13 -> Airport | E13: =Sheet2_Cleaned_Data!M13 -> 930581.7 | F13: =Sheet5_Multiple_Regression!$J$6+Sheet5_Multiple_Regression!$J$7*Sheet5_Multiple_Regression!A14+Sheet5_Multiple_Regression!$J$8*Sheet5_Multiple_Regression!B14+Sheet5_Multiple_Regression!$J$9*Sheet5_Multiple_Regression!C14+Sheet5_Multiple_Regression!$J$10*Sheet5_Multiple_Regression!D14+Sheet5_Multiple_Regression!$J$11*Sheet5_Multiple_Regression!E14+Sheet5_Multiple_Regression!$J$12*Sheet5_Multiple_Regression!F14+Sheet5_Multiple_Regression!$J$13*Sheet5_Multiple_Regression!G14 -> 865386.51 | G13: =E13-F13 -> 65195.186 | I13: Rank | J13: store_id | K13: store_type | L13: region | M13: residual
A14: =Sheet2_Cleaned_Data!A14 -> STR-1003 | B14: =Sheet2_Cleaned_Data!B14 -> 2025-02-01 | C14: =Sheet2_Cleaned_Data!C14 -> North | D14: =Sheet2_Cleaned_Data!D14 -> Airport | E14: =Sheet2_Cleaned_Data!M14 -> 779010.94 | F14: =Sheet5_Multiple_Regression!$J$6+Sheet5_Multiple_Regression!$J$7*Sheet5_Multiple_Regression!A15+Sheet5_Multiple_Regression!$J$8*Sheet5_Multiple_Regression!B15+Sheet5_Multiple_Regression!$J$9*Sheet5_Multiple_Regression!C15+Sheet5_Multiple_Regression!$J$10*Sheet5_Multiple_Regression!D15+Sheet5_Multiple_Regression!$J$11*Sheet5_Multiple_Regression!E15+Sheet5_Multiple_Regression!$J$12*Sheet5_Multiple_Regression!F15+Sheet5_Multiple_Regression!$J$13*Sheet5_Multiple_Regression!G15 -> 798799.07 | G14: =E14-F14 -> -19788.129 | I14: 1 | J14: =INDEX($A$5:$A$324,MATCH(M14,$G$5:$G$324,0)) -> STR-1017 | K14: =INDEX($D$5:$D$324,MATCH(M14,$G$5:$G$324,0)) -> High Street | L14: =INDEX($C$5:$C$324,MATCH(M14,$G$5:$G$324,0)) -> West | M14: =SMALL($G$5:$G$324,1) -> -159241.23
A15: =Sheet2_Cleaned_Data!A15 -> STR-1003 | B15: =Sheet2_Cleaned_Data!B15 -> 2025-03-01 | C15: =Sheet2_Cleaned_Data!C15 -> North | D15: =Sheet2_Cleaned_Data!D15 -> Airport | E15: =Sheet2_Cleaned_Data!M15 -> 723060.76 | F15: =Sheet5_Multiple_Regression!$J$6+Sheet5_Multiple_Regression!$J$7*Sheet5_Multiple_Regression!A16+Sheet5_Multiple_Regression!$J$8*Sheet5_Multiple_Regression!B16+Sheet5_Multiple_Regression!$J$9*Sheet5_Multiple_Regression!C16+Sheet5_Multiple_Regression!$J$10*Sheet5_Multiple_Regression!D16+Sheet5_Multiple_Regression!$J$11*Sheet5_Multiple_Regression!E16+Sheet5_Multiple_Regression!$J$12*Sheet5_Multiple_Regression!F16+Sheet5_Multiple_Regression!$J$13*Sheet5_Multiple_Regression!G16 -> 760003.9 | G15: =E15-F15 -> -36943.143 | I15: 2 | J15: =INDEX($A$5:$A$324,MATCH(M15,$G$5:$G$324,0)) -> STR-1023 | K15: =INDEX($D$5:$D$324,MATCH(M15,$G$5:$G$324,0)) -> Mall | L15: =INDEX($C$5:$C$324,MATCH(M15,$G$5:$G$324,0)) -> South | M15: =SMALL($G$5:$G$324,2) -> -128265.26
A16: =Sheet2_Cleaned_Data!A16 -> STR-1003 | B16: =Sheet2_Cleaned_Data!B16 -> 2025-04-01 | C16: =Sheet2_Cleaned_Data!C16 -> North | D16: =Sheet2_Cleaned_Data!D16 -> Airport | E16: =Sheet2_Cleaned_Data!M16 -> 910791.94 | F16: =Sheet5_Multiple_Regression!$J$6+Sheet5_Multiple_Regression!$J$7*Sheet5_Multiple_Regression!A17+Sheet5_Multiple_Regression!$J$8*Sheet5_Multiple_Regression!B17+Sheet5_Multiple_Regression!$J$9*Sheet5_Multiple_Regression!C17+Sheet5_Multiple_Regression!$J$10*Sheet5_Multiple_Regression!D17+Sheet5_Multiple_Regression!$J$11*Sheet5_Multiple_Regression!E17+Sheet5_Multiple_Regression!$J$12*Sheet5_Multiple_Regression!F17+Sheet5_Multiple_Regression!$J$13*Sheet5_Multiple_Regression!G17 -> 871984.85 | G16: =E16-F16 -> 38807.089 | I16: 3 | J16: =INDEX($A$5:$A$324,MATCH(M16,$G$5:$G$324,0)) -> STR-1012 | K16: =INDEX($D$5:$D$324,MATCH(M16,$G$5:$G$324,0)) -> Residential | L16: =INDEX($C$5:$C$324,MATCH(M16,$G$5:$G$324,0)) -> West | M16: =SMALL($G$5:$G$324,3) -> -121078.89
A17: =Sheet2_Cleaned_Data!A17 -> STR-1004 | B17: =Sheet2_Cleaned_Data!B17 -> 2025-01-01 | C17: =Sheet2_Cleaned_Data!C17 -> East | D17: =Sheet2_Cleaned_Data!D17 -> Residential | E17: =Sheet2_Cleaned_Data!M17 -> 922168.6 | F17: =Sheet5_Multiple_Regression!$J$6+Sheet5_Multiple_Regression!$J$7*Sheet5_Multiple_Regression!A18+Sheet5_Multiple_Regression!$J$8*Sheet5_Multiple_Regression!B18+Sheet5_Multiple_Regression!$J$9*Sheet5_Multiple_Regression!C18+Sheet5_Multiple_Regression!$J$10*Sheet5_Multiple_Regression!D18+Sheet5_Multiple_Regression!$J$11*Sheet5_Multiple_Regression!E18+Sheet5_Multiple_Regression!$J$12*Sheet5_Multiple_Regression!F18+Sheet5_Multiple_Regression!$J$13*Sheet5_Multiple_Regression!G18 -> 872478.78 | G17: =E17-F17 -> 49689.822 | I17: 4 | J17: =INDEX($A$5:$A$324,MATCH(M17,$G$5:$G$324,0)) -> STR-1007 | K17: =INDEX($D$5:$D$324,MATCH(M17,$G$5:$G$324,0)) -> Mall | L17: =INDEX($C$5:$C$324,MATCH(M17,$G$5:$G$324,0)) -> West | M17: =SMALL($G$5:$G$324,4) -> -99820.541
A18: =Sheet2_Cleaned_Data!A18 -> STR-1004 | B18: =Sheet2_Cleaned_Data!B18 -> 2025-02-01 | C18: =Sheet2_Cleaned_Data!C18 -> East | D18: =Sheet2_Cleaned_Data!D18 -> Residential | E18: =Sheet2_Cleaned_Data!M18 -> 726606.28 | F18: =Sheet5_Multiple_Regression!$J$6+Sheet5_Multiple_Regression!$J$7*Sheet5_Multiple_Regression!A19+Sheet5_Multiple_Regression!$J$8*Sheet5_Multiple_Regression!B19+Sheet5_Multiple_Regression!$J$9*Sheet5_Multiple_Regression!C19+Sheet5_Multiple_Regression!$J$10*Sheet5_Multiple_Regression!D19+Sheet5_Multiple_Regression!$J$11*Sheet5_Multiple_Regression!E19+Sheet5_Multiple_Regression!$J$12*Sheet5_Multiple_Regression!F19+Sheet5_Multiple_Regression!$J$13*Sheet5_Multiple_Regression!G19 -> 769936.36 | G18: =E18-F18 -> -43330.085 | I18: 5 | J18: =INDEX($A$5:$A$324,MATCH(M18,$G$5:$G$324,0)) -> STR-1009 | K18: =INDEX($D$5:$D$324,MATCH(M18,$G$5:$G$324,0)) -> Residential | L18: =INDEX($C$5:$C$324,MATCH(M18,$G$5:$G$324,0)) -> North | M18: =SMALL($G$5:$G$324,5) -> -98450.319
A19: =Sheet2_Cleaned_Data!A19 -> STR-1004 | B19: =Sheet2_Cleaned_Data!B19 -> 2025-03-01 | C19: =Sheet2_Cleaned_Data!C19 -> East | D19: =Sheet2_Cleaned_Data!D19 -> Residential | E19: =Sheet2_Cleaned_Data!M19 -> 746501.09 | F19: =Sheet5_Multiple_Regression!$J$6+Sheet5_Multiple_Regression!$J$7*Sheet5_Multiple_Regression!A20+Sheet5_Multiple_Regression!$J$8*Sheet5_Multiple_Regression!B20+Sheet5_Multiple_Regression!$J$9*Sheet5_Multiple_Regression!C20+Sheet5_Multiple_Regression!$J$10*Sheet5_Multiple_Regression!D20+Sheet5_Multiple_Regression!$J$11*Sheet5_Multiple_Regression!E20+Sheet5_Multiple_Regression!$J$12*Sheet5_Multiple_Regression!F20+Sheet5_Multiple_Regression!$J$13*Sheet5_Multiple_Regression!G20 -> 742679.03 | G19: =E19-F19 -> 3822.0632
A20: =Sheet2_Cleaned_Data!A20 -> STR-1004 | B20: =Sheet2_Cleaned_Data!B20 -> 2025-04-01 | C20: =Sheet2_Cleaned_Data!C20 -> East | D20: =Sheet2_Cleaned_Data!D20 -> Residential | E20: =Sheet2_Cleaned_Data!M20 -> 834017.02 | F20: =Sheet5_Multiple_Regression!$J$6+Sheet5_Multiple_Regression!$J$7*Sheet5_Multiple_Regression!A21+Sheet5_Multiple_Regression!$J$8*Sheet5_Multiple_Regression!B21+Sheet5_Multiple_Regression!$J$9*Sheet5_Multiple_Regression!C21+Sheet5_Multiple_Regression!$J$10*Sheet5_Multiple_Regression!D21+Sheet5_Multiple_Regression!$J$11*Sheet5_Multiple_Regression!E21+Sheet5_Multiple_Regression!$J$12*Sheet5_Multiple_Regression!F21+Sheet5_Multiple_Regression!$J$13*Sheet5_Multiple_Regression!G21 -> 805632.61 | G20: =E20-F20 -> 28384.411
A21: =Sheet2_Cleaned_Data!A21 -> STR-1005 | B21: =Sheet2_Cleaned_Data!B21 -> 2025-01-01 | C21: =Sheet2_Cleaned_Data!C21 -> South | D21: =Sheet2_Cleaned_Data!D21 -> Residential | E21: =Sheet2_Cleaned_Data!M21 -> 666152.52 | F21: =Sheet5_Multiple_Regression!$J$6+Sheet5_Multiple_Regression!$J$7*Sheet5_Multiple_Regression!A22+Sheet5_Multiple_Regression!$J$8*Sheet5_Multiple_Regression!B22+Sheet5_Multiple_Regression!$J$9*Sheet5_Multiple_Regression!C22+Sheet5_Multiple_Regression!$J$10*Sheet5_Multiple_Regression!D22+Sheet5_Multiple_Regression!$J$11*Sheet5_Multiple_Regression!E22+Sheet5_Multiple_Regression!$J$12*Sheet5_Multiple_Regression!F22+Sheet5_Multiple_Regression!$J$13*Sheet5_Multiple_Regression!G22 -> 677698.74 | G21: =E21-F21 -> -11546.218
A22: =Sheet2_Cleaned_Data!A22 -> STR-1005 | B22: =Sheet2_Cleaned_Data!B22 -> 2025-02-01 | C22: =Sheet2_Cleaned_Data!C22 -> South | D22: =Sheet2_Cleaned_Data!D22 -> Residential | E22: =Sheet2_Cleaned_Data!M22 -> 573155.19 | F22: =Sheet5_Multiple_Regression!$J$6+Sheet5_Multiple_Regression!$J$7*Sheet5_Multiple_Regression!A23+Sheet5_Multiple_Regression!$J$8*Sheet5_Multiple_Regression!B23+Sheet5_Multiple_Regression!$J$9*Sheet5_Multiple_Regression!C23+Sheet5_Multiple_Regression!$J$10*Sheet5_Multiple_Regression!D23+Sheet5_Multiple_Regression!$J$11*Sheet5_Multiple_Regression!E23+Sheet5_Multiple_Regression!$J$12*Sheet5_Multiple_Regression!F23+Sheet5_Multiple_Regression!$J$13*Sheet5_Multiple_Regression!G23 -> 588643.82 | G22: =E22-F22 -> -15488.63
A23: =Sheet2_Cleaned_Data!A23 -> STR-1005 | B23: =Sheet2_Cleaned_Data!B23 -> 2025-03-01 | C23: =Sheet2_Cleaned_Data!C23 -> South | D23: =Sheet2_Cleaned_Data!D23 -> Residential | E23: =Sheet2_Cleaned_Data!M23 -> 666573.2 | F23: =Sheet5_Multiple_Regression!$J$6+Sheet5_Multiple_Regression!$J$7*Sheet5_Multiple_Regression!A24+Sheet5_Multiple_Regression!$J$8*Sheet5_Multiple_Regression!B24+Sheet5_Multiple_Regression!$J$9*Sheet5_Multiple_Regression!C24+Sheet5_Multiple_Regression!$J$10*Sheet5_Multiple_Regression!D24+Sheet5_Multiple_Regression!$J$11*Sheet5_Multiple_Regression!E24+Sheet5_Multiple_Regression!$J$12*Sheet5_Multiple_Regression!F24+Sheet5_Multiple_Regression!$J$13*Sheet5_Multiple_Regression!G24 -> 681060.9 | G23: =E23-F23 -> -14487.703
A24: =Sheet2_Cleaned_Data!A24 -> STR-1005 | B24: =Sheet2_Cleaned_Data!B24 -> 2025-04-01 | C24: =Sheet2_Cleaned_Data!C24 -> South | D24: =Sheet2_Cleaned_Data!D24 -> Residential | E24: =Sheet2_Cleaned_Data!M24 -> 591619.95 | F24: =Sheet5_Multiple_Regression!$J$6+Sheet5_Multiple_Regression!$J$7*Sheet5_Multiple_Regression!A25+Sheet5_Multiple_Regression!$J$8*Sheet5_Multiple_Regression!B25+Sheet5_Multiple_Regression!$J$9*Sheet5_Multiple_Regression!C25+Sheet5_Multiple_Regression!$J$10*Sheet5_Multiple_Regression!D25+Sheet5_Multiple_Regression!$J$11*Sheet5_Multiple_Regression!E25+Sheet5_Multiple_Regression!$J$12*Sheet5_Multiple_Regression!F25+Sheet5_Multiple_Regression!$J$13*Sheet5_Multiple_Regression!G25 -> 588111.5 | G24: =E24-F24 -> 3508.4507
A25: =Sheet2_Cleaned_Data!A25 -> STR-1006 | B25: =Sheet2_Cleaned_Data!B25 -> 2025-01-01 | C25: =Sheet2_Cleaned_Data!C25 -> North | D25: =Sheet2_Cleaned_Data!D25 -> Residential | E25: =Sheet2_Cleaned_Data!M25 -> 415721.82 | F25: =Sheet5_Multiple_Regression!$J$6+Sheet5_Multiple_Regression!$J$7*Sheet5_Multiple_Regression!A26+Sheet5_Multiple_Regression!$J$8*Sheet5_Multiple_Regression!B26+Sheet5_Multiple_Regression!$J$9*Sheet5_Multiple_Regression!C26+Sheet5_Multiple_Regression!$J$10*Sheet5_Multiple_Regression!D26+Sheet5_Multiple_Regression!$J$11*Sheet5_Multiple_Regression!E26+Sheet5_Multiple_Regression!$J$12*Sheet5_Multiple_Regression!F26+Sheet5_Multiple_Regression!$J$13*Sheet5_Multiple_Regression!G26 -> 491609.47 | G25: =E25-F25 -> -75887.649
A26: =Sheet2_Cleaned_Data!A26 -> STR-1006 | B26: =Sheet2_Cleaned_Data!B26 -> 2025-02-01 | C26: =Sheet2_Cleaned_Data!C26 -> North | D26: =Sheet2_Cleaned_Data!D26 -> Residential | E26: =Sheet2_Cleaned_Data!M26 -> 491905.13 | F26: =Sheet5_Multiple_Regression!$J$6+Sheet5_Multiple_Regression!$J$7*Sheet5_Multiple_Regression!A27+Sheet5_Multiple_Regression!$J$8*Sheet5_Multiple_Regression!B27+Sheet5_Multiple_Regression!$J$9*Sheet5_Multiple_Regression!C27+Sheet5_Multiple_Regression!$J$10*Sheet5_Multiple_Regression!D27+Sheet5_Multiple_Regression!$J$11*Sheet5_Multiple_Regression!E27+Sheet5_Multiple_Regression!$J$12*Sheet5_Multiple_Regression!F27+Sheet5_Multiple_Regression!$J$13*Sheet5_Multiple_Regression!G27 -> 486041.78 | G26: =E26-F26 -> 5863.3521
A27: =Sheet2_Cleaned_Data!A27 -> STR-1006 | B27: =Sheet2_Cleaned_Data!B27 -> 2025-03-01 | C27: =Sheet2_Cleaned_Data!C27 -> North | D27: =Sheet2_Cleaned_Data!D27 -> Residential | E27: =Sheet2_Cleaned_Data!M27 -> 555929.4 | F27: =Sheet5_Multiple_Regression!$J$6+Sheet5_Multiple_Regression!$J$7*Sheet5_Multiple_Regression!A28+Sheet5_Multiple_Regression!$J$8*Sheet5_Multiple_Regression!B28+Sheet5_Multiple_Regression!$J$9*Sheet5_Multiple_Regression!C28+Sheet5_Multiple_Regression!$J$10*Sheet5_Multiple_Regression!D28+Sheet5_Multiple_Regression!$J$11*Sheet5_Multiple_Regression!E28+Sheet5_Multiple_Regression!$J$12*Sheet5_Multiple_Regression!F28+Sheet5_Multiple_Regression!$J$13*Sheet5_Multiple_Regression!G28 -> 519517.9 | G27: =E27-F27 -> 36411.503
A28: =Sheet2_Cleaned_Data!A28 -> STR-1006 | B28: =Sheet2_Cleaned_Data!B28 -> 2025-04-01 | C28: =Sheet2_Cleaned_Data!C28 -> North | D28: =Sheet2_Cleaned_Data!D28 -> Residential | E28: =Sheet2_Cleaned_Data!M28 -> 565810.99 | F28: =Sheet5_Multiple_Regression!$J$6+Sheet5_Multiple_Regression!$J$7*Sheet5_Multiple_Regression!A29+Sheet5_Multiple_Regression!$J$8*Sheet5_Multiple_Regression!B29+Sheet5_Multiple_Regression!$J$9*Sheet5_Multiple_Regression!C29+Sheet5_Multiple_Regression!$J$10*Sheet5_Multiple_Regression!D29+Sheet5_Multiple_Regression!$J$11*Sheet5_Multiple_Regression!E29+Sheet5_Multiple_Regression!$J$12*Sheet5_Multiple_Regression!F29+Sheet5_Multiple_Regression!$J$13*Sheet5_Multiple_Regression!G29 -> 544317.11 | G28: =E28-F28 -> 21493.878
A29: =Sheet2_Cleaned_Data!A29 -> STR-1007 | B29: =Sheet2_Cleaned_Data!B29 -> 2025-01-01 | C29: =Sheet2_Cleaned_Data!C29 -> West | D29: =Sheet2_Cleaned_Data!D29 -> Mall | E29: =Sheet2_Cleaned_Data!M29 -> 811771.14 | F29: =Sheet5_Multiple_Regression!$J$6+Sheet5_Multiple_Regression!$J$7*Sheet5_Multiple_Regression!A30+Sheet5_Multiple_Regression!$J$8*Sheet5_Multiple_Regression!B30+Sheet5_Multiple_Regression!$J$9*Sheet5_Multiple_Regression!C30+Sheet5_Multiple_Regression!$J$10*Sheet5_Multiple_Regression!D30+Sheet5_Multiple_Regression!$J$11*Sheet5_Multiple_Regression!E30+Sheet5_Multiple_Regression!$J$12*Sheet5_Multiple_Regression!F30+Sheet5_Multiple_Regression!$J$13*Sheet5_Multiple_Regression!G30 -> 836959.02 | G29: =E29-F29 -> -25187.881
A30: =Sheet2_Cleaned_Data!A30 -> STR-1007 | B30: =Sheet2_Cleaned_Data!B30 -> 2025-02-01 | C30: =Sheet2_Cleaned_Data!C30 -> West | D30: =Sheet2_Cleaned_Data!D30 -> Mall | E30: =Sheet2_Cleaned_Data!M30 -> 800451.94 | F30: =Sheet5_Multiple_Regression!$J$6+Sheet5_Multiple_Regression!$J$7*Sheet5_Multiple_Regression!A31+Sheet5_Multiple_Regression!$J$8*Sheet5_Multiple_Regression!B31+Sheet5_Multiple_Regression!$J$9*Sheet5_Multiple_Regression!C31+Sheet5_Multiple_Regression!$J$10*Sheet5_Multiple_Regression!D31+Sheet5_Multiple_Regression!$J$11*Sheet5_Multiple_Regression!E31+Sheet5_Multiple_Regression!$J$12*Sheet5_Multiple_Regression!F31+Sheet5_Multiple_Regression!$J$13*Sheet5_Multiple_Regression!G31 -> 900272.48 | G30: =E30-F30 -> -99820.541
... A324: =Sheet2_Cleaned_Data!A324 -> STR-1080 | B324: =Sheet2_Cleaned_Data!B324 -> 2025-04-01 | C324: =Sheet2_Cleaned_Data!C324 -> East | D324: =Sheet2_Cleaned_Data!D324 -> Residential | E324: =Sheet2_Cleaned_Data!M324 -> 559660.84 | F324: =Sheet5_Multiple_Regression!$J$6+Sheet5_Multiple_Regression!$J$7*Sheet5_Multiple_Regression!A325+Sheet5_Multiple_Regression!$J$8*Sheet5_Multiple_Regression!B325+Sheet5_Multiple_Regression!$J$9*Sheet5_Multiple_Regression!C325+Sheet5_Multiple_Regression!$J$10*Sheet5_Multiple_Regression!D325+Sheet5_Multiple_Regression!$J$11*Sheet5_Multiple_Regression!E325+Sheet5_Multiple_Regression!$J$12*Sheet5_Multiple_Regression!F325+Sheet5_Multiple_Regression!$J$13*Sheet5_Multiple_Regression!G325 -> 589874.67 | G324: =E324-F324 -> -30213.829

Sheet Sheet7_Model_Comparison
A1: Model Comparison Summary
A3: Model | B3: Independent Variable(s) | C3: R-squared | D3: Key p-value(s) | E3: Significant?
A4: Simple: monthly_sales ~ marketing_spend | B4: marketing_spend | C4: =Sheet4_Simple_Regression!B7 -> 0.16724469 | D4: =Sheet4_Simple_Regression!B9 -> 2.4800615e-14 | E4: =IF(D4<0.05,"Yes","No") -> Yes
A5: Simple: monthly_sales ~ footfall | B5: footfall | C5: =Sheet4_Simple_Regression!B15 -> 0.73628534 | D5: =Sheet4_Simple_Regression!B17 -> 4.7503615e-94 | E5: =IF(D5<0.05,"Yes","No") -> Yes
A6: Simple: monthly_sales ~ avg_discount_pct | B6: avg_discount_pct | C6: =Sheet4_Simple_Regression!B23 -> 0.008290503 | D6: =Sheet4_Simple_Regression!B25 -> 0.10399305 | E6: =IF(D6<0.05,"Yes","No") -> No
A7: Simple: monthly_sales ~ inventory_availability_pct | B7: inventory_availability_pct | C7: =Sheet4_Simple_Regression!B31 -> 0.013115016 | D7: =Sheet4_Simple_Regression!B33 -> 0.040625297 | E7: =IF(D7<0.05,"Yes","No") -> Yes
A8: Simple: monthly_sales ~ customer_rating (cleaned) | B8: customer_rating (cleaned) | C8: =Sheet4_Simple_Regression!B39 -> 0.00069845266 | D8: =Sheet4_Simple_Regression!B41 -> 0.63764415 | E8: =IF(D8<0.05,"Yes","No") -> No
A9: Multiple Regression (final model) | B9: marketing_spend, footfall, avg_discount_pct, inventory_availability_pct, store_type dummies | C9: =Sheet5_Multiple_Regression!J15 -> 0.82139228 | D9: See sheet 5 for individual p-values | E9: Mostly yes (footfall, marketing_spend, inventory_availability_pct, st_Residential)
